Workbook

Sheet ukr_admgz_adm0
A1: ADM0_PCODE | B1: ADM1_COUNT | C1: ADM2_COUNT | D1: ADM3_COUNT | E1: ADM4_COUNT
A2: UA | B2: 27 | C2: 139 | D2: 1769 | E2: 29708

Sheet ukr_admgz_adm1
A1: ADM0_PCODE | B1: ADM1_PCODE | C1: Minrehion_CODE | D1: KOATUU_CODE | E1: ADM2_COUNT | F1: ADM3_COUNT | G1: ADM4_COUNT
A2: =LEFT(B2,2) -> UA | B2: UA01 | C2: UA01000000000013043 | D2: 0100000000 | E2: =COUNTIF(ukr_admgz_adm2!B:B,ukr_admgz_adm1!B2) -> 10 | F2: =COUNTIF(ukr_admgz_adm3!B:B,ukr_admgz_adm1!B2) -> 297 | G2: =COUNTIF(ukr_admgz_adm4!B:B,ukr_admgz_adm1!B2) -> 1050
A3: =LEFT(B3,2) -> UA | B3: UA71 | C3: UA71000000000010357 | D3: 7100000000 | E3: =COUNTIF(ukr_admgz_adm2!B:B,ukr_admgz_adm1!B3) -> 4 | F3: =COUNTIF(ukr_admgz_adm3!B:B,ukr_admgz_adm1!B3) -> 66 | G3: =COUNTIF(ukr_admgz_adm4!B:B,ukr_admgz_adm1!B3) -> 854
A4: =LEFT(B4,2) -> UA | B4: UA74 | C4: UA74000000000025378 | D4: 7400000000 | E4: =COUNTIF(ukr_admgz_adm2!B:B,ukr_admgz_adm1!B4) -> 5 | F4: =COUNTIF(ukr_admgz_adm3!B:B,ukr_admgz_adm1!B4) -> 57 | G4: =COUNTIF(ukr_admgz_adm4!B:B,ukr_admgz_adm1!B4) -> 1509
A5: =LEFT(B5,2) -> UA | B5: UA73 | C5: UA73000000000044923 | D5: 7300000000 | E5: =COUNTIF(ukr_admgz_adm2!B:B,ukr_admgz_adm1!B5) -> 3 | F5: =COUNTIF(ukr_admgz_adm3!B:B,ukr_admgz_adm1!B5) -> 52 | G5: =COUNTIF(ukr_admgz_adm4!B:B,ukr_admgz_adm1!B5) -> 417
A6: =LEFT(B6,2) -> UA | B6: UA12 | C6: UA12000000000090473 | D6: 1200000000 | E6: =COUNTIF(ukr_admgz_adm2!B:B,ukr_admgz_adm1!B6) -> 7 | F6: =COUNTIF(ukr_admgz_adm3!B:B,ukr_admgz_adm1!B6) -> 86 | G6: =COUNTIF(ukr_admgz_adm4!B:B,ukr_admgz_adm1!B6) -> 1500
A7: =LEFT(B7,2) -> UA | B7: UA14 | C7: UA14000000000091971 | D7: 1400000000 | E7: =COUNTIF(ukr_admgz_adm2!B:B,ukr_admgz_adm1!B7) -> 8 | F7: =COUNTIF(ukr_admgz_adm3!B:B,ukr_admgz_adm1!B7) -> 66 | G7: =COUNTIF(ukr_admgz_adm4!B:B,ukr_admgz_adm1!B7) -> 1298
A8: =LEFT(B8,2) -> UA | B8: UA26 | C8: UA26000000000069363 | D8: 2600000000 | E8: =COUNTIF(ukr_admgz_adm2!B:B,ukr_admgz_adm1!B8) -> 6 | F8: =COUNTIF(ukr_admgz_adm3!B:B,ukr_admgz_adm1!B8) -> 62 | G8: =COUNTIF(ukr_admgz_adm4!B:B,ukr_admgz_adm1!B8) -> 805
A9: =LEFT(B9,2) -> UA | B9: UA63 | C9: UA63000000000041885 | D9: 6300000000 | E9: =COUNTIF(ukr_admgz_adm2!B:B,ukr_admgz_adm1!B9) -> 7 | F9: =COUNTIF(ukr_admgz_adm3!B:B,ukr_admgz_adm1!B9) -> 56 | G9: =COUNTIF(ukr_admgz_adm4!B:B,ukr_admgz_adm1!B9) -> 1751
A10: =LEFT(B10,2) -> UA | B10: UA65 | C10: UA65000000000030969 | D10: 6500000000 | E10: =COUNTIF(ukr_admgz_adm2!B:B,ukr_admgz_adm1!B10) -> 5 | F10: =COUNTIF(ukr_admgz_adm3!B:B,ukr_admgz_adm1!B10) -> 49 | G10: =COUNTIF(ukr_admgz_adm4!B:B,ukr_admgz_adm1!B10) -> 696
A11: =LEFT(B11,2) -> UA | B11: UA68 | C11: UA68000000000099709 | D11: 6800000000 | E11: =COUNTIF(ukr_admgz_adm2!B:B,ukr_admgz_adm1!B11) -> 3 | F11: =COUNTIF(ukr_admgz_adm3!B:B,ukr_admgz_adm1!B11) -> 60 | G11: =COUNTIF(ukr_admgz_adm4!B:B,ukr_admgz_adm1!B11) -> 1451
A12: =LEFT(B12,2) -> UA | B12: UA35 | C12: UA35000000000016081 | D12: 3500000000 | E12: =COUNTIF(ukr_admgz_adm2!B:B,ukr_admgz_adm1!B12) -> 4 | F12: =COUNTIF(ukr_admgz_adm3!B:B,ukr_admgz_adm1!B12) -> 49 | G12: =COUNTIF(ukr_admgz_adm4!B:B,ukr_admgz_adm1!B12) -> 1027
A13: =LEFT(B13,2) -> UA | B13: UA80 | E13: =COUNTIF(ukr_admgz_adm2!B:B,ukr_admgz_adm1!B13) -> 1 | F13: =COUNTIF(ukr_admgz_adm3!B:B,ukr_admgz_adm1!B13) -> 1 | G13: =COUNTIF(ukr_admgz_adm4!B:B,ukr_admgz_adm1!B13) -> 1
A14: =LEFT(B14,2) -> UA | B14: UA32 | C14: UA32000000000030281 | D14: 3200000000 | E14: =COUNTIF(ukr_admgz_adm2!B:B,ukr_admgz_adm1!B14) -> 8 | F14: =COUNTIF(ukr_admgz_adm3!B:B,ukr_admgz_adm1!B14) -> 70 | G14: =COUNTIF(ukr_admgz_adm4!B:B,ukr_admgz_adm1!B14) -> 1182
A15: =LEFT(B15,2) -> UA | B15: UA44 | C15: UA44000000000018893 | D15: 4400000000 | E15: =COUNTIF(ukr_admgz_adm2!B:B,ukr_admgz_adm1!B15) -> 8 | F15: =COUNTIF(ukr_admgz_adm3!B:B,ukr_admgz_adm1!B15) -> 37 | G15: =COUNTIF(ukr_admgz_adm4!B:B,ukr_admgz_adm1!B15) -> 926
A16: =LEFT(B16,2) -> UA | B16: UA46 | C16: UA46000000000026241 | D16: 4600000000 | E16: =COUNTIF(ukr_admgz_adm2!B:B,ukr_admgz_adm1!B16) -> 7 | F16: =COUNTIF(ukr_admgz_adm3!B:B,ukr_admgz_adm1!B16) -> 73 | G16: =COUNTIF(ukr_admgz_adm4!B:B,ukr_admgz_adm1!B16) -> 1927
A17: =LEFT(B17,2) -> UA | B17: UA48 | C17: UA48000000000039575 | D17: 4800000000 | E17: =COUNTIF(ukr_admgz_adm2!B:B,ukr_admgz_adm1!B17) -> 4 | F17: =COUNTIF(ukr_admgz_adm3!B:B,ukr_admgz_adm1!B17) -> 52 | G17: =COUNTIF(ukr_admgz_adm4!B:B,ukr_admgz_adm1!B17) -> 911
A18: =LEFT(B18,2) -> UA | B18: UA51 | C18: UA51000000000030770 | D18: 5100000000 | E18: =COUNTIF(ukr_admgz_adm2!B:B,ukr_admgz_adm1!B18) -> 7 | F18: =COUNTIF(ukr_admgz_adm3!B:B,ukr_admgz_adm1!B18) -> 91 | G18: =COUNTIF(ukr_admgz_adm4!B:B,ukr_admgz_adm1!B18) -> 1174
A19: =LEFT(B19,2) -> UA | B19: UA53 | C19: UA53000000000028050 | D19: 5300000000 | E19: =COUNTIF(ukr_admgz_adm2!B:B,ukr_admgz_adm1!B19) -> 4 | F19: =COUNTIF(ukr_admgz_adm3!B:B,ukr_admgz_adm1!B19) -> 60 | G19: =COUNTIF(ukr_admgz_adm4!B:B,ukr_admgz_adm1!B19) -> 1839
A20: =LEFT(B20,2) -> UA | B20: UA56 | C20: UA56000000000066151 | D20: 5600000000 | E20: =COUNTIF(ukr_admgz_adm2!B:B,ukr_admgz_adm1!B20) -> 4 | F20: =COUNTIF(ukr_admgz_adm3!B:B,ukr_admgz_adm1!B20) -> 64 | G20: =COUNTIF(ukr_admgz_adm4!B:B,ukr_admgz_adm1!B20) -> 1026
A21: =LEFT(B21,2) -> UA | B21: UA85 | E21: =COUNTIF(ukr_admgz_adm2!B:B,ukr_admgz_adm1!B21) -> 1 | F21: =COUNTIF(ukr_admgz_adm3!B:B,ukr_admgz_adm1!B21) -> 1 | G21: =COUNTIF(ukr_admgz_adm4!B:B,ukr_admgz_adm1!B21) -> 1
A22: =LEFT(B22,2) -> UA | B22: UA59 | C22: UA59000000000057109 | D22: 5900000000 | E22: =COUNTIF(ukr_admgz_adm2!B:B,ukr_admgz_adm1!B22) -> 5 | F22: =COUNTIF(ukr_admgz_adm3!B:B,ukr_admgz_adm1!B22) -> 51 | G22: =COUNTIF(ukr_admgz_adm4!B:B,ukr_admgz_adm1!B22) -> 1489
A23: =LEFT(B23,2) -> UA | B23: UA61 | C23: UA61000000000060328 | D23: 6100000000 | E23: =COUNTIF(ukr_admgz_adm2!B:B,ukr_admgz_adm1!B23) -> 3 | F23: =COUNTIF(ukr_admgz_adm3!B:B,ukr_admgz_adm1!B23) -> 55 | G23: =COUNTIF(ukr_admgz_adm4!B:B,ukr_admgz_adm1!B23) -> 1058
A24: =LEFT(B24,2) -> UA | B24: UA05 | C24: UA05000000000010236 | D24: 0500000000 | E24: =COUNTIF(ukr_admgz_adm2!B:B,ukr_admgz_adm1!B24) -> 6 | F24: =COUNTIF(ukr_admgz_adm3!B:B,ukr_admgz_adm1!B24) -> 63 | G24: =COUNTIF(ukr_admgz_adm4!B:B,ukr_admgz_adm1!B24) -> 1503
A25: =LEFT(B25,2) -> UA | B25: UA07 | C25: UA07000000000024379 | D25: 0700000000 | E25: =COUNTIF(ukr_admgz_adm2!B:B,ukr_admgz_adm1!B25) -> 4 | F25: =COUNTIF(ukr_admgz_adm3!B:B,ukr_admgz_adm1!B25) -> 54 | G25: =COUNTIF(ukr_admgz_adm4!B:B,ukr_admgz_adm1!B25) -> 1087
A26: =LEFT(B26,2) -> UA | B26: UA21 | C26: UA21000000000011690 | D26: 2100000000 | E26: =COUNTIF(ukr_admgz_adm2!B:B,ukr_admgz_adm1!B26) -> 6 | F26: =COUNTIF(ukr_admgz_adm3!B:B,ukr_admgz_adm1!B26) -> 64 | G26: =COUNTIF(ukr_admgz_adm4!B:B,ukr_admgz_adm1!B26) -> 608
A27: =LEFT(B27,2) -> UA | B27: UA23 | C27: UA23000000000064947 | D27: 2300000000 | E27: =COUNTIF(ukr_admgz_adm2!B:B,ukr_admgz_adm1!B27) -> 5 | F27: =COUNTIF(ukr_admgz_adm3!B:B,ukr_admgz_adm1!B27) -> 67 | G27: =COUNTIF(ukr_admgz_adm4!B:B,ukr_admgz_adm1!B27) -> 950
A28: =LEFT(B28,2) -> UA | B28: UA18 | C28: UA18000000000041385 | D28: 1800000000 | E28: =COUNTIF(ukr_admgz_adm2!B:B,ukr_admgz_adm1!B28) -> 4 | F28: =COUNTIF(ukr_admgz_adm3!B:B,ukr_admgz_adm1!B28) -> 66 | G28: =COUNTIF(ukr_admgz_adm4!B:B,ukr_admgz_adm1!B28) -> 1668

Sheet ukr_admgz_adm2
A1: ADM0_PCODE | B1: ADM1_PCODE | C1: ADM2_PCODE | D1: Minrehion_CODE | E1: KOATUU_CODE | F1: ADM3_COUNT | G1: ADM4_COUNT
A2: =LEFT(C2,2) -> UA | B2: =LEFT(C2,4) -> UA01 | C2: UA0102 | D2: UA01020000000022387 | E2: 0120400000 | F2: =COUNTIF(ukr_admgz_adm3!C:C,ukr_admgz_adm2!C2) -> 18 | G2: =COUNTIF(ukr_admgz_adm4!C:C,ukr_admgz_adm2!C2) -> 116
A3: =LEFT(C3,2) -> UA | B3: =LEFT(C3,4) -> UA01 | C3: UA0104 | D3: UA01040000000069938 | E3: 0120700000 | F3: =COUNTIF(ukr_admgz_adm3!C:C,ukr_admgz_adm2!C3) -> 38 | G3: =COUNTIF(ukr_admgz_adm4!C:C,ukr_admgz_adm2!C3) -> 138
A4: =LEFT(C4,2) -> UA | B4: =LEFT(C4,4) -> UA01 | C4: UA0106 | D4: UA01060000000028159 | E4: 0121100000 | F4: =COUNTIF(ukr_admgz_adm3!C:C,ukr_admgz_adm2!C4) -> 29 | G4: =COUNTIF(ukr_admgz_adm4!C:C,ukr_admgz_adm2!C4) -> 114
A5: =LEFT(C5,2) -> UA | B5: =LEFT(C5,4) -> UA01 | C5: UA0108 | D5: UA01080000000090798 | F5: =COUNTIF(ukr_admgz_adm3!C:C,ukr_admgz_adm2!C5) -> 40 | G5: =COUNTIF(ukr_admgz_adm4!C:C,ukr_admgz_adm2!C5) -> 118
A6: =LEFT(C6,2) -> UA | B6: =LEFT(C6,4) -> UA01 | C6: UA0110 | D6: UA01100000000047924 | F6: =COUNTIF(ukr_admgz_adm3!C:C,ukr_admgz_adm2!C6) -> 28 | G6: =COUNTIF(ukr_admgz_adm4!C:C,ukr_admgz_adm2!C6) -> 69
A7: =LEFT(C7,2) -> UA | B7: =LEFT(C7,4) -> UA01 | C7: UA0112 | D7: UA01120000000061837 | F7: =COUNTIF(ukr_admgz_adm3!C:C,ukr_admgz_adm2!C7) -> 37 | G7: =COUNTIF(ukr_admgz_adm4!C:C,ukr_admgz_adm2!C7) -> 126
A8: =LEFT(C8,2) -> UA | B8: =LEFT(C8,4) -> UA01 | C8: UA0114 | D8: UA01140000000010124 | E8: 0122300000 | F8: =COUNTIF(ukr_admgz_adm3!C:C,ukr_admgz_adm2!C8) -> 27 | G8: =COUNTIF(ukr_admgz_adm4!C:C,ukr_admgz_adm2!C8) -> 84
A9: =LEFT(C9,2) -> UA | B9: =LEFT(C9,4) -> UA01 | C9: UA0116 | D9: UA01160000000090126 | F9: =COUNTIF(ukr_admgz_adm3!C:C,ukr_admgz_adm2!C9) -> 24 | G9: =COUNTIF(ukr_admgz_adm4!C:C,ukr_admgz_adm2!C9) -> 115
A10: =LEFT(C10,2) -> UA | B10: =LEFT(C10,4) -> UA01 | C10: UA0118 | D10: UA01180000000068971 | F10: =COUNTIF(ukr_admgz_adm3!C:C,ukr_admgz_adm2!C10) -> 40 | G10: =COUNTIF(ukr_admgz_adm4!C:C,ukr_admgz_adm2!C10) -> 112
A11: =LEFT(C11,2) -> UA | B11: =LEFT(C11,4) -> UA01 | C11: UA0120 | D11: UA01200000000063976 | F11: =COUNTIF(ukr_admgz_adm3!C:C,ukr_admgz_adm2!C11) -> 16 | G11: =COUNTIF(ukr_admgz_adm4!C:C,ukr_admgz_adm2!C11) -> 58
A12: =LEFT(C12,2) -> UA | B12: =LEFT(C12,4) -> UA05 | C12: UA0502 | D12: UA05020000000026686 | E12: 0520600000 | F12: =COUNTIF(ukr_admgz_adm3!C:C,ukr_admgz_adm2!C12) -> 16 | G12: =COUNTIF(ukr_admgz_adm4!C:C,ukr_admgz_adm2!C12) -> 410
A13: =LEFT(C13,2) -> UA | B13: =LEFT(C13,4) -> UA05 | C13: UA0504 | D13: UA05040000000050292 | E13: 0520800000 | F13: =COUNTIF(ukr_admgz_adm3!C:C,ukr_admgz_adm2!C13) -> 14 | G13: =COUNTIF(ukr_admgz_adm4!C:C,ukr_admgz_adm2!C13) -> 264
A14: =LEFT(C14,2) -> UA | B14: =LEFT(C14,4) -> UA05 | C14: UA0506 | D14: UA05060000000061926 | E14: 0521000000 | F14: =COUNTIF(ukr_admgz_adm3!C:C,ukr_admgz_adm2!C14) -> 8 | G14: =COUNTIF(ukr_admgz_adm4!C:C,ukr_admgz_adm2!C14) -> 216
A15: =LEFT(C15,2) -> UA | B15: =LEFT(C15,4) -> UA05 | C15: UA0508 | D15: UA05080000000040234 | E15: 0522600000 | F15: =COUNTIF(ukr_admgz_adm3!C:C,ukr_admgz_adm2!C15) -> 7 | G15: =COUNTIF(ukr_admgz_adm4!C:C,ukr_admgz_adm2!C15) -> 195
A16: =LEFT(C16,2) -> UA | B16: =LEFT(C16,4) -> UA05 | C16: UA0510 | D16: UA05100000000022396 | E16: 0524300000 | F16: =COUNTIF(ukr_admgz_adm3!C:C,ukr_admgz_adm2!C16) -> 9 | G16: =COUNTIF(ukr_admgz_adm4!C:C,ukr_admgz_adm2!C16) -> 189
A17: =LEFT(C17,2) -> UA | B17: =LEFT(C17,4) -> UA05 | C17: UA0512 | D17: UA05120000000017020 | E17: 0524800000 | F17: =COUNTIF(ukr_admgz_adm3!C:C,ukr_admgz_adm2!C17) -> 9 | G17: =COUNTIF(ukr_admgz_adm4!C:C,ukr_admgz_adm2!C17) -> 229
A18: =LEFT(C18,2) -> UA | B18: =LEFT(C18,4) -> UA07 | C18: UA0702 | D18: UA07020000000048211 | E18: 0720500000 | F18: =COUNTIF(ukr_admgz_adm3!C:C,ukr_admgz_adm2!C18) -> 11 | G18: =COUNTIF(ukr_admgz_adm4!C:C,ukr_admgz_adm2!C18) -> 201
A19: =LEFT(C19,2) -> UA | B19: =LEFT(C19,4) -> UA07 | C19: UA0704 | D19: UA07040000000026412 | E19: 0721400000 | F19: =COUNTIF(ukr_admgz_adm3!C:C,ukr_admgz_adm2!C19) -> 5 | G19: =COUNTIF(ukr_admgz_adm4!C:C,ukr_admgz_adm2!C19) -> 155
A20: =LEFT(C20,2) -> UA | B20: =LEFT(C20,4) -> UA07 | C20: UA0706 | D20: UA07060000000092268 | E20: 0722100000 | F20: =COUNTIF(ukr_admgz_adm3!C:C,ukr_admgz_adm2!C20) -> 23 | G20: =COUNTIF(ukr_admgz_adm4!C:C,ukr_admgz_adm2!C20) -> 380
A21: =LEFT(C21,2) -> UA | B21: =LEFT(C21,4) -> UA07 | C21: UA0708 | D21: UA07080000000034745 | E21: 0722800000 | F21: =COUNTIF(ukr_admgz_adm3!C:C,ukr_admgz_adm2!C21) -> 15 | G21: =COUNTIF(ukr_admgz_adm4!C:C,ukr_admgz_adm2!C21) -> 351
A22: =LEFT(C22,2) -> UA | B22: =LEFT(C22,4) -> UA12 | C22: UA1202 | D22: UA12020000000052809 | E22: 1221400000 | F22: =COUNTIF(ukr_admgz_adm3!C:C,ukr_admgz_adm2!C22) -> 17 | G22: =COUNTIF(ukr_admgz_adm4!C:C,ukr_admgz_adm2!C22) -> 234
A23: =LEFT(C23,2) -> UA | B23: =LEFT(C23,4) -> UA12 | C23: UA1204 | D23: UA12040000000032213 | F23: =COUNTIF(ukr_admgz_adm3!C:C,ukr_admgz_adm2!C23) -> 12 | G23: =COUNTIF(ukr_admgz_adm4!C:C,ukr_admgz_adm2!C23) -> 274
A24: =LEFT(C24,2) -> UA | B24: =LEFT(C24,4) -> UA12 | C24: UA1206 | D24: UA12060000000022633 | E24: 1221800000 | F24: =COUNTIF(ukr_admgz_adm3!C:C,ukr_admgz_adm2!C24) -> 15 | G24: =COUNTIF(ukr_admgz_adm4!C:C,ukr_admgz_adm2!C24) -> 282
A25: =LEFT(C25,2) -> UA | B25: =LEFT(C25,4) -> UA12 | C25: UA1208 | D25: UA12080000000023578 | E25: 1222900000 | F25: =COUNTIF(ukr_admgz_adm3!C:C,ukr_admgz_adm2!C25) -> 8 | G25: =COUNTIF(ukr_admgz_adm4!C:C,ukr_admgz_adm2!C25) -> 130
A26: =LEFT(C26,2) -> UA | B26: =LEFT(C26,4) -> UA12 | C26: UA1210 | D26: UA12100000000039307 | E26: 1223200000 | F26: =COUNTIF(ukr_admgz_adm3!C:C,ukr_admgz_adm2!C26) -> 8 | G26: =COUNTIF(ukr_admgz_adm4!C:C,ukr_admgz_adm2!C26) -> 110
A27: =LEFT(C27,2) -> UA | B27: =LEFT(C27,4) -> UA12 | C27: UA1212 | D27: UA12120000000089862 | E27: 1223500000 | F27: =COUNTIF(ukr_admgz_adm3!C:C,ukr_admgz_adm2!C27) -> 7 | G27: =COUNTIF(ukr_admgz_adm4!C:C,ukr_admgz_adm2!C27) -> 98
A28: =LEFT(C28,2) -> UA | B28: =LEFT(C28,4) -> UA12 | C28: UA1214 | D28: UA12140000000011720 | E28: 1224800000 | F28: =COUNTIF(ukr_admgz_adm3!C:C,ukr_admgz_adm2!C28) -> 19 | G28: =COUNTIF(ukr_admgz_adm4!C:C,ukr_admgz_adm2!C28) -> 372
A29: =LEFT(C29,2) -> UA | B29: =LEFT(C29,4) -> UA14 | C29: UA1402 | D29: UA14020000000013572 | E29: 1420900000 | F29: =COUNTIF(ukr_admgz_adm3!C:C,ukr_admgz_adm2!C29) -> 7 | G29: =COUNTIF(ukr_admgz_adm4!C:C,ukr_admgz_adm2!C29) -> 112
A30: =LEFT(C30,2) -> UA | B30: =LEFT(C30,4) -> UA14 | C30: UA1404 | D30: UA14040000000098211 | E30: 1421500000 | F30: =COUNTIF(ukr_admgz_adm3!C:C,ukr_admgz_adm2!C30) -> 8 | G30: =COUNTIF(ukr_admgz_adm4!C:C,ukr_admgz_adm2!C30) -> 158
A31: =LEFT(C31,2) -> UA | B31: =LEFT(C31,4) -> UA14 | C31: UA1406 | D31: UA14060000000024357 | F31: =COUNTIF(ukr_admgz_adm3!C:C,ukr_admgz_adm2!C31) -> 9 | G31: =COUNTIF(ukr_admgz_adm4!C:C,ukr_admgz_adm2!C31) -> 132
A32: =LEFT(C32,2) -> UA | B32: =LEFT(C32,4) -> UA14 | C32: UA1408 | D32: UA14080000000098686 | F32: =COUNTIF(ukr_admgz_adm3!C:C,ukr_admgz_adm2!C32) -> 6 | G32: =COUNTIF(ukr_admgz_adm4!C:C,ukr_admgz_adm2!C32) -> 152
A33: =LEFT(C33,2) -> UA | B33: =LEFT(C33,4) -> UA14 | C33: UA1410 | D33: UA14100000000010319 | F33: =COUNTIF(ukr_admgz_adm3!C:C,ukr_admgz_adm2!C33) -> 5 | G33: =COUNTIF(ukr_admgz_adm4!C:C,ukr_admgz_adm2!C33) -> 156
A34: =LEFT(C34,2) -> UA | B34: =LEFT(C34,4) -> UA14 | C34: UA1412 | D34: UA14120000000070232 | F34: =COUNTIF(ukr_admgz_adm3!C:C,ukr_admgz_adm2!C34) -> 12 | G34: =COUNTIF(ukr_admgz_adm4!C:C,ukr_admgz_adm2!C34) -> 235
A35: =LEFT(C35,2) -> UA | B35: =LEFT(C35,4) -> UA14 | C35: UA1414 | D35: UA14140000000070889 | F35: =COUNTIF(ukr_admgz_adm3!C:C,ukr_admgz_adm2!C35) -> 5 | G35: =COUNTIF(ukr_admgz_adm4!C:C,ukr_admgz_adm2!C35) -> 89
A36: =LEFT(C36,2) -> UA | B36: =LEFT(C36,4) -> UA14 | C36: UA1416 | D36: UA14160000000061982 | E36: 1422700000 | F36: =COUNTIF(ukr_admgz_adm3!C:C,ukr_admgz_adm2!C36) -> 14 | G36: =COUNTIF(ukr_admgz_adm4!C:C,ukr_admgz_adm2!C36) -> 264
A37: =LEFT(C37,2) -> UA | B37: =LEFT(C37,4) -> UA18 | C37: UA1802 | D37: UA18020000000072859 | E37: 1820800000 | F37: =COUNTIF(ukr_admgz_adm3!C:C,ukr_admgz_adm2!C37) -> 10 | G37: =COUNTIF(ukr_admgz_adm4!C:C,ukr_admgz_adm2!C37) -> 162
A38: =LEFT(C38,2) -> UA | B38: =LEFT(C38,4) -> UA18 | C38: UA1804 | D38: UA18040000000058965 | E38: 1822000000 | F38: =COUNTIF(ukr_admgz_adm3!C:C,ukr_admgz_adm2!C38) -> 31 | G38: =COUNTIF(ukr_admgz_adm4!C:C,ukr_admgz_adm2!C38) -> 684
A39: =LEFT(C39,2) -> UA | B39: =LEFT(C39,4) -> UA18 | C39: UA1806 | D39: UA18060000000021754 | E39: 1822300000 | F39: =COUNTIF(ukr_admgz_adm3!C:C,ukr_admgz_adm2!C39) -> 13 | G39: =COUNTIF(ukr_admgz_adm4!C:C,ukr_admgz_adm2!C39) -> 529
A40: =LEFT(C40,2) -> UA | B40: =LEFT(C40,4) -> UA18 | C40: UA1808 | D40: UA18080000000016657 | E40: 1824000000 | F40: =COUNTIF(ukr_admgz_adm3!C:C,ukr_admgz_adm2!C40) -> 12 | G40: =COUNTIF(ukr_admgz_adm4!C:C,ukr_admgz_adm2!C40) -> 293
...

Sheet ukr_admgz_adm3
A1: ADM0_PCODE | B1: ADM1_PCODE | C1: ADM2_PCODE | D1: ADM3_PCODE | E1: Minrehion_CODE | F1: KOATUU_CODE | G1: ADM4_COUNT
A2: UA | B2: UA01 | C2: UA0102 | D2: UA0102003 | E2: UA01020030000085835 | F2: 0120480400 | G2: =COUNTIF(ukr_admgz_adm4!D:D,ukr_admgz_adm3!D2) -> 5
A3: UA | B3: UA01 | C3: UA0102 | D3: UA0102005 | E3: UA01020050000056842 | F3: 0120410100 | G3: =COUNTIF(ukr_admgz_adm4!D:D,ukr_admgz_adm3!D3) -> 2
A4: UA | B4: UA01 | C4: UA0102 | D4: UA0102009 | E4: UA01020090000085519 | F4: 0120480800 | G4: =COUNTIF(ukr_admgz_adm4!D:D,ukr_admgz_adm3!D4) -> 6
A5: UA | B5: UA01 | C5: UA0102 | D5: UA0102011 | E5: UA01020110000025392 | F5: 0120481300 | G5: =COUNTIF(ukr_admgz_adm4!D:D,ukr_admgz_adm3!D5) -> 2
A6: UA | B6: UA01 | C6: UA0102 | D6: UA0102013 | E6: UA01020130000011846 | F6: 0120481900 | G6: =COUNTIF(ukr_admgz_adm4!D:D,ukr_admgz_adm3!D6) -> 9
A7: UA | B7: UA01 | C7: UA0102 | D7: UA0102015 | E7: UA01020150000013553 | F7: 0120482200 | G7: =COUNTIF(ukr_admgz_adm4!D:D,ukr_admgz_adm3!D7) -> 3
A8: UA | B8: UA01 | C8: UA0102 | D8: UA0102017 | E8: UA01020170000026113 | F8: 0120482500 | G8: =COUNTIF(ukr_admgz_adm4!D:D,ukr_admgz_adm3!D8) -> 7
A9: UA | B9: UA01 | C9: UA0102 | D9: UA0102019 | E9: UA01020190000077808 | F9: 0120482900 | G9: =COUNTIF(ukr_admgz_adm4!D:D,ukr_admgz_adm3!D9) -> 6
A10: UA | B10: UA01 | C10: UA0102 | D10: UA0102025 | E10: UA01020250000083187 | F10: 0120483600 | G10: =COUNTIF(ukr_admgz_adm4!D:D,ukr_admgz_adm3!D10) -> 4
A11: UA | B11: UA01 | C11: UA0102 | D11: UA0102027 | E11: UA01020270000095791 | F11: 0120483900 | G11: =COUNTIF(ukr_admgz_adm4!D:D,ukr_admgz_adm3!D11) -> 4
A12: UA | B12: UA01 | C12: UA0102 | D12: UA0102029 | E12: UA01020290000023695 | F12: 0120455300 | G12: =COUNTIF(ukr_admgz_adm4!D:D,ukr_admgz_adm3!D12) -> 6
A13: UA | B13: UA01 | C13: UA0102 | D13: UA0102033 | E13: UA01020330000026857 | F13: 0120484400 | G13: =COUNTIF(ukr_admgz_adm4!D:D,ukr_admgz_adm3!D13) -> 2
... A826: UA | B826: UA26 | C826: UA2612 | D826: UA2612015 | E826: UA26120150000021671 | F826: 2611000000 | G826: =COUNTIF(ukr_admgz_adm4!D:D,ukr_admgz_adm3!D826) -> 2
A827: UA | B827: UA32 | C827: UA3200 | D827: UA3200000 | G827: =COUNTIF(ukr_admgz_adm4!D:D,ukr_admgz_adm3!D827) -> 2
A828: UA | B828: UA32 | C828: UA3202 | D828: UA3202001 | E828: UA32020010000093088 | F828: 3210300000 | G828: =COUNTIF(ukr_admgz_adm4!D:D,ukr_admgz_adm3!D828) -> 17
A829: UA | B829: UA32 | C829: UA3202 | D829: UA3202003 | E829: UA32020030000029575 | F829: 3221655100 | G829: =COUNTIF(ukr_admgz_adm4!D:D,ukr_admgz_adm3!D829) -> 34
A830: UA | B830: UA32 | C830: UA3202 | D830: UA3202005 | E830: UA32020050000062595 | F830: 3221455500 | G830: =COUNTIF(ukr_admgz_adm4!D:D,ukr_admgz_adm3!D830) -> 12
A831: UA | B831: UA32 | C831: UA3202 | D831: UA3202007 | E831: UA32020070000027895 | F831: 3221483600 | G831: =COUNTIF(ukr_admgz_adm4!D:D,ukr_admgz_adm3!D831) -> 9
A832: UA | B832: UA32 | C832: UA3202 | D832: UA3202009 | E832: UA32020090000022264 | F832: 3220483300 | G832: =COUNTIF(ukr_admgz_adm4!D:D,ukr_admgz_adm3!D832) -> 21
A833: UA | B833: UA32 | C833: UA3202 | D833: UA3202011 | E833: UA32020110000085875 | F833: 3220683200 | G833: =COUNTIF(ukr_admgz_adm4!D:D,ukr_admgz_adm3!D833) -> 12
A834: UA | B834: UA32 | C834: UA3202 | D834: UA3202013 | E834: UA32020130000010013 | F834: 3223755100 | G834: =COUNTIF(ukr_admgz_adm4!D:D,ukr_admgz_adm3!D834) -> 23
A835: UA | B835: UA32 | C835: UA3202 | D835: UA3202015 | E835: UA32020150000040878 | F835: 3224010100 | G835: =COUNTIF(ukr_admgz_adm4!D:D,ukr_admgz_adm3!D835) -> 45
A836: UA | B836: UA32 | C836: UA3202 | D836: UA3202017 | E836: UA32020170000020698 | F836: 3224255100 | G836: =COUNTIF(ukr_admgz_adm4!D:D,ukr_admgz_adm3!D836) -> 30
A837: UA | B837: UA32 | C837: UA3202 | D837: UA3202019 | E837: UA32020190000084133 | F837: 3224410100 | G837: =COUNTIF(ukr_admgz_adm4!D:D,ukr_admgz_adm3!D837) -> 35
A838: UA | B838: UA32 | C838: UA3202 | D838: UA3202021 | E838: UA32020210000064694 | F838: 3224610100 | G838: =COUNTIF(ukr_admgz_adm4!D:D,ukr_admgz_adm3!D838) -> 33
A839: UA | B839: UA32 | C839: UA3202 | D839: UA3202023 | E839: UA32020230000012716 | F839: 3220410500 | G839: =COUNTIF(ukr_admgz_adm4!D:D,ukr_admgz_adm3!D839) -> 20
... A1768: UA | B1768: UA74 | C1768: UA7410 | D1768: UA7410039 | E1768: UA74100390000073425 | F1768: 7410100000 | G1768: =COUNTIF(ukr_admgz_adm4!D:D,ukr_admgz_adm3!D1768) -> 1
A1769: UA | B1769: UA80 | C1769: UA8000 | D1769: UA8000000 | G1769: =COUNTIF(ukr_admgz_adm4!D:D,ukr_admgz_adm3!D1769) -> 1
A1770: UA | B1770: UA85 | C1770: UA8500 | D1770: UA8500000 | G1770: =COUNTIF(ukr_admgz_adm4!D:D,ukr_admgz_adm3!D1770) -> 1

Sheet ukr_admgz_adm4
A1: ADM0_PCODE | B1: ADM1_PCODE | C1: ADM2_PCODE | D1: ADM3_PCODE | E1: ADM4_PCODE | F1: Minrehion_CODE | G1: KOATUU_CODE
A2: =LEFT(E2,2) -> UA | B2: =LEFT(E2,4) -> UA01 | C2: =LEFT(E2,6) -> UA0102 | D2: =LEFT(E2,9) -> UA0102001 | E2: UA0102001001 | F2: UA01020010010075540 | G2: 8536990201
A3: =LEFT(E3,2) -> UA | B3: =LEFT(E3,4) -> UA01 | C3: =LEFT(E3,6) -> UA0102 | D3: =LEFT(E3,9) -> UA0102001 | E3: UA0102001002 | F3: UA01020010020030666 | G3: 8536990203
A4: =LEFT(E4,2) -> UA | B4: =LEFT(E4,4) -> UA01 | C4: =LEFT(E4,6) -> UA0102 | D4: =LEFT(E4,9) -> UA0102003 | E4: UA0102003001 | F4: UA01020030010043419 | G4: 0120480401
A5: =LEFT(E5,2) -> UA | B5: =LEFT(E5,4) -> UA01 | C5: =LEFT(E5,6) -> UA0102 | D5: =LEFT(E5,9) -> UA0102003 | E5: UA0102003002 | F5: UA01020030020095516 | G5: 0120480402
A6: =LEFT(E6,2) -> UA | B6: =LEFT(E6,4) -> UA01 | C6: =LEFT(E6,6) -> UA0102 | D6: =LEFT(E6,9) -> UA0102003 | E6: UA0102003003 | F6: UA01020030030055891 | G6: 0120480403
A7: =LEFT(E7,2) -> UA | B7: =LEFT(E7,4) -> UA01 | C7: =LEFT(E7,6) -> UA0102 | D7: =LEFT(E7,9) -> UA0102003 | E7: UA0102003004 | F7: UA01020030040087481 | G7: 0120480404
A8: =LEFT(E8,2) -> UA | B8: =LEFT(E8,4) -> UA01 | C8: =LEFT(E8,6) -> UA0102 | D8: =LEFT(E8,9) -> UA0102003 | E8: UA0102003005 | F8: UA01020030050049624 | G8: 0120480405
A9: =LEFT(E9,2) -> UA | B9: =LEFT(E9,4) -> UA01 | C9: =LEFT(E9,6) -> UA0102 | D9: =LEFT(E9,9) -> UA0102005 | E9: UA0102005001 | F9: UA01020050010045207 | G9: 0120410100
A10: =LEFT(E10,2) -> UA | B10: =LEFT(E10,4) -> UA01 | C10: =LEFT(E10,6) -> UA0102 | D10: =LEFT(E10,9) -> UA0102005 | E10: UA0102005002 | F10: UA01020050020067441 | G10: 0120445100
A11: =LEFT(E11,2) -> UA | B11: =LEFT(E11,4) -> UA01 | C11: =LEFT(E11,6) -> UA0102 | D11: =LEFT(E11,9) -> UA0102007 | E11: UA0102007001 | F11: UA01020070010032091 | G11: 8536990501
A12: =LEFT(E12,2) -> UA | B12: =LEFT(E12,4) -> UA01 | C12: =LEFT(E12,6) -> UA0102 | D12: =LEFT(E12,9) -> UA0102007 | E12: UA0102007002 | F12: UA01020070020014815 | G12: 8536990503
A13: =LEFT(E13,2) -> UA | B13: =LEFT(E13,4) -> UA01 | C13: =LEFT(E13,6) -> UA0102 | D13: =LEFT(E13,9) -> UA0102007 | E13: UA0102007003 | F13: UA01020070030047085 | G13: 8536990504
... A10027: =LEFT(E10027,2) -> UA | B10027: =LEFT(E10027,4) -> UA26 | C10027: =LEFT(E10027,6) -> UA2604 | D10027: =LEFT(E10027,9) -> UA2604039 | E10027: UA2604039007 | F10027: UA26040390070080034 | G10027: 2625888604
A10028: =LEFT(E10028,2) -> UA | B10028: =LEFT(E10028,4) -> UA26 | C10028: =LEFT(E10028,6) -> UA2604 | D10028: =LEFT(E10028,9) -> UA2604039 | E10028: UA2604039008 | F10028: UA26040390080042180
A10029: =LEFT(E10029,2) -> UA | B10029: =LEFT(E10029,4) -> UA26 | C10029: =LEFT(E10029,6) -> UA2606 | D10029: =LEFT(E10029,9) -> UA2606001 | E10029: UA2606001001 | F10029: UA26060010010092713 | G10029: 2610200000
A10030: =LEFT(E10030,2) -> UA | B10030: =LEFT(E10030,4) -> UA26 | C10030: =LEFT(E10030,6) -> UA2606 | D10030: =LEFT(E10030,9) -> UA2606001 | E10030: UA2606001002 | F10030: UA26060010020045600 | G10030: 2610291602
A10031: =LEFT(E10031,2) -> UA | B10031: =LEFT(E10031,4) -> UA26 | C10031: =LEFT(E10031,6) -> UA2606 | D10031: =LEFT(E10031,9) -> UA2606001 | E10031: UA2606001003 | F10031: UA26060010030047962 | G10031: 2610291603
A10032: =LEFT(E10032,2) -> UA | B10032: =LEFT(E10032,4) -> UA26 | C10032: =LEFT(E10032,6) -> UA2606 | D10032: =LEFT(E10032,9) -> UA2606001 | E10032: UA2606001004 | F10032: UA26060010040047878 | G10032: 2610290601
A10033: =LEFT(E10033,2) -> UA | B10033: =LEFT(E10033,4) -> UA26 | C10033: =LEFT(E10033,6) -> UA2606 | D10033: =LEFT(E10033,9) -> UA2606001 | E10033: UA2606001005 | F10033: UA26060010050051072 | G10033: 2610291403
A10034: =LEFT(E10034,2) -> UA | B10034: =LEFT(E10034,4) -> UA26 | C10034: =LEFT(E10034,6) -> UA2606 | D10034: =LEFT(E10034,9) -> UA2606001 | E10034: UA2606001006 | F10034: UA26060010060012260 | G10034: 2610291001
A10035: =LEFT(E10035,2) -> UA | B10035: =LEFT(E10035,4) -> UA26 | C10035: =LEFT(E10035,6) -> UA2606 | D10035: =LEFT(E10035,9) -> UA2606001 | E10035: UA2606001007 | F10035: UA26060010070093416 | G10035: 2610291401
A10036: =LEFT(E10036,2) -> UA | B10036: =LEFT(E10036,4) -> UA26 | C10036: =LEFT(E10036,6) -> UA2606 | D10036: =LEFT(E10036,9) -> UA2606001 | E10036: UA2606001008 | F10036: UA26060010080019736 | G10036: 2610291601
A10037: =LEFT(E10037,2) -> UA | B10037: =LEFT(E10037,4) -> UA26 | C10037: =LEFT(E10037,6) -> UA2606 | D10037: =LEFT(E10037,9) -> UA2606001 | E10037: UA2606001009 | F10037: UA26060010090024376 | G10037: 2610291002
A10038: =LEFT(E10038,2) -> UA | B10038: =LEFT(E10038,4) -> UA26 | C10038: =LEFT(E10038,6) -> UA2606 | D10038: =LEFT(E10038,9) -> UA2606001 | E10038: UA2606001010 | F10038: UA26060010100042353 | G10038: 2610292005
A10039: =LEFT(E10039,2) -> UA | B10039: =LEFT(E10039,4) -> UA26 | C10039: =LEFT(E10039,6) -> UA2606 | D10039: =LEFT(E10039,9) -> UA2606001 | E10039: UA2606001011 | F10039: UA26060010110044887 | G10039: 2610292001
A10040: =LEFT(E10040,2) -> UA | B10040: =LEFT(E10040,4) -> UA26 | C10040: =LEFT(E10040,6) -> UA2606 | D10040: =LEFT(E10040,9) -> UA2606003 | E10040: UA2606003001 | F10040: UA26060030010070530 | G10040: 2624855400
... A29709: =LEFT(E29709,2) -> UA | B29709: =LEFT(E29709,4) -> UA85 | C29709: =LEFT(E29709,6) -> UA8500 | D29709: =LEFT(E29709,9) -> UA8500000 | E29709: UA8500000000 | F29709: UA85000000000065278 | G29709: 8500000000
